Workbook

Sheet 금리 통합비교
A1: 월 | B1: 집계기준 | C1: 금리 항목 (상위 > 하위) | D1: 중요도 | E1: 기준금리 (월말, 연 %) | F1: 평균시장금리 (연 %) | G1: iM뱅크금리 (연 %) | H1: iM−시장 (%p) | I1: 시장−기준 (%p) | J1: iM−기준 (%p) | K1: 비교 역할 | L1: 비교 안내 | M1: 시장 항목코드 | N1: 시장 원본 파일 | O1: 시장 원본 셀 | P1: iM 원본 파일 | Q1: iM 원본 셀
A2: 45992 | B2: 잔액 | C2: 대출 > 기업 | D2: 1 핵심 | E2: =LOOKUP(EOMONTH(A2,0),'출처 및 기준'!$A$34:$A$53,'출처 및 기준'!$B$34:$B$53) -> 0.025 | F2: 0.0418 | G2: 0.0438 | H2: =IF(COUNT(F2:G2)=2,ROUND((G2-F2)*100,2),"") -> 0.2 | I2: =IF(COUNT(E2:F2)=2,ROUND((F2-E2)*100,2),"") -> 1.68 | J2: =IF(AND(ISNUMBER(E2),ISNUMBER(G2)),ROUND((G2-E2)*100,2),"") -> 1.88 | K2: 기업대출 핵심 비교 | M2: BECBLB0201 | N2: ECOS각종금리데이터.xlsx | O2: 데이터!BA20 | P2: iM뱅크금리2025(잔액).xlsx | Q2: Sheet1!N3
A3: 45962 | B3: 잔액 | C3: 대출 > 기업 | D3: 1 핵심 | E3: =LOOKUP(EOMONTH(A3,0),'출처 및 기준'!$A$34:$A$53,'출처 및 기준'!$B$34:$B$53) -> 0.025 | F3: 0.0415 | G3: 0.0435 | H3: =IF(COUNT(F3:G3)=2,ROUND((G3-F3)*100,2),"") -> 0.2 | I3: =IF(COUNT(E3:F3)=2,ROUND((F3-E3)*100,2),"") -> 1.65 | J3: =IF(AND(ISNUMBER(E3),ISNUMBER(G3)),ROUND((G3-E3)*100,2),"") -> 1.85 | K3: 기업대출 핵심 비교 | M3: BECBLB0201 | N3: ECOS각종금리데이터.xlsx | O3: 데이터!AZ20 | P3: iM뱅크금리2025(잔액).xlsx | Q3: Sheet1!M3
A4: 45931 | B4: 잔액 | C4: 대출 > 기업 | D4: 1 핵심 | E4: =LOOKUP(EOMONTH(A4,0),'출처 및 기준'!$A$34:$A$53,'출처 및 기준'!$B$34:$B$53) -> 0.025 | F4: 0.0414 | G4: 0.0434 | H4: =IF(COUNT(F4:G4)=2,ROUND((G4-F4)*100,2),"") -> 0.2 | I4: =IF(COUNT(E4:F4)=2,ROUND((F4-E4)*100,2),"") -> 1.64 | J4: =IF(AND(ISNUMBER(E4),ISNUMBER(G4)),ROUND((G4-E4)*100,2),"") -> 1.84 | K4: 기업대출 핵심 비교 | M4: BECBLB0201 | N4: ECOS각종금리데이터.xlsx | O4: 데이터!AY20 | P4: iM뱅크금리2025(잔액).xlsx | Q4: Sheet1!L3
A5: 45901 | B5: 잔액 | C5: 대출 > 기업 | D5: 1 핵심 | E5: =LOOKUP(EOMONTH(A5,0),'출처 및 기준'!$A$34:$A$53,'출처 및 기준'!$B$34:$B$53) -> 0.025 | F5: 0.0416 | G5: 0.0435 | H5: =IF(COUNT(F5:G5)=2,ROUND((G5-F5)*100,2),"") -> 0.19 | I5: =IF(COUNT(E5:F5)=2,ROUND((F5-E5)*100,2),"") -> 1.66 | J5: =IF(AND(ISNUMBER(E5),ISNUMBER(G5)),ROUND((G5-E5)*100,2),"") -> 1.85 | K5: 기업대출 핵심 비교 | M5: BECBLB0201 | N5: ECOS각종금리데이터.xlsx | O5: 데이터!AX20 | P5: iM뱅크금리2025(잔액).xlsx | Q5: Sheet1!K3
A6: 45870 | B6: 잔액 | C6: 대출 > 기업 | D6: 1 핵심 | E6: =LOOKUP(EOMONTH(A6,0),'출처 및 기준'!$A$34:$A$53,'출처 및 기준'!$B$34:$B$53) -> 0.025 | F6: 0.042 | G6: 0.0441 | H6: =IF(COUNT(F6:G6)=2,ROUND((G6-F6)*100,2),"") -> 0.21 | I6: =IF(COUNT(E6:F6)=2,ROUND((F6-E6)*100,2),"") -> 1.7 | J6: =IF(AND(ISNUMBER(E6),ISNUMBER(G6)),ROUND((G6-E6)*100,2),"") -> 1.91 | K6: 기업대출 핵심 비교 | M6: BECBLB0201 | N6: ECOS각종금리데이터.xlsx | O6: 데이터!AW20 | P6: iM뱅크금리2025(잔액).xlsx | Q6: Sheet1!J3
A7: 45839 | B7: 잔액 | C7: 대출 > 기업 | D7: 1 핵심 | E7: =LOOKUP(EOMONTH(A7,0),'출처 및 기준'!$A$34:$A$53,'출처 및 기준'!$B$34:$B$53) -> 0.025 | F7: 0.0425 | G7: 0.0445 | H7: =IF(COUNT(F7:G7)=2,ROUND((G7-F7)*100,2),"") -> 0.2 | I7: =IF(COUNT(E7:F7)=2,ROUND((F7-E7)*100,2),"") -> 1.75 | J7: =IF(AND(ISNUMBER(E7),ISNUMBER(G7)),ROUND((G7-E7)*100,2),"") -> 1.95 | K7: 기업대출 핵심 비교 | M7: BECBLB0201 | N7: ECOS각종금리데이터.xlsx | O7: 데이터!AV20 | P7: iM뱅크금리2025(잔액).xlsx | Q7: Sheet1!I3
A8: 45809 | B8: 잔액 | C8: 대출 > 기업 | D8: 1 핵심 | E8: =LOOKUP(EOMONTH(A8,0),'출처 및 기준'!$A$34:$A$53,'출처 및 기준'!$B$34:$B$53) -> 0.025 | F8: 0.043 | G8: 0.0451 | H8: =IF(COUNT(F8:G8)=2,ROUND((G8-F8)*100,2),"") -> 0.21 | I8: =IF(COUNT(E8:F8)=2,ROUND((F8-E8)*100,2),"") -> 1.8 | J8: =IF(AND(ISNUMBER(E8),ISNUMBER(G8)),ROUND((G8-E8)*100,2),"") -> 2.01 | K8: 기업대출 핵심 비교 | M8: BECBLB0201 | N8: ECOS각종금리데이터.xlsx | O8: 데이터!AU20 | P8: iM뱅크금리2025(잔액).xlsx | Q8: Sheet1!H3
A9: 45778 | B9: 잔액 | C9: 대출 > 기업 | D9: 1 핵심 | E9: =LOOKUP(EOMONTH(A9,0),'출처 및 기준'!$A$34:$A$53,'출처 및 기준'!$B$34:$B$53) -> 0.025 | F9: 0.0438 | G9: 0.0463 | H9: =IF(COUNT(F9:G9)=2,ROUND((G9-F9)*100,2),"") -> 0.25 | I9: =IF(COUNT(E9:F9)=2,ROUND((F9-E9)*100,2),"") -> 1.88 | J9: =IF(AND(ISNUMBER(E9),ISNUMBER(G9)),ROUND((G9-E9)*100,2),"") -> 2.13 | K9: 기업대출 핵심 비교 | M9: BECBLB0201 | N9: ECOS각종금리데이터.xlsx | O9: 데이터!AT20 | P9: iM뱅크금리2025(잔액).xlsx | Q9: Sheet1!G3
A10: 45748 | B10: 잔액 | C10: 대출 > 기업 | D10: 1 핵심 | E10: =LOOKUP(EOMONTH(A10,0),'출처 및 기준'!$A$34:$A$53,'출처 및 기준'!$B$34:$B$53) -> 0.0275 | F10: 0.0446 | G10: 0.0471 | H10: =IF(COUNT(F10:G10)=2,ROUND((G10-F10)*100,2),"") -> 0.25 | I10: =IF(COUNT(E10:F10)=2,ROUND((F10-E10)*100,2),"") -> 1.71 | J10: =IF(AND(ISNUMBER(E10),ISNUMBER(G10)),ROUND((G10-E10)*100,2),"") -> 1.96 | K10: 기업대출 핵심 비교 | M10: BECBLB0201 | N10: ECOS각종금리데이터.xlsx | O10: 데이터!AS20 | P10: iM뱅크금리2025(잔액).xlsx | Q10: Sheet1!F3
A11: 45717 | B11: 잔액 | C11: 대출 > 기업 | D11: 1 핵심 | E11: =LOOKUP(EOMONTH(A11,0),'출처 및 기준'!$A$34:$A$53,'출처 및 기준'!$B$34:$B$53) -> 0.0275 | F11: 0.0454 | G11: 0.0479 | H11: =IF(COUNT(F11:G11)=2,ROUND((G11-F11)*100,2),"") -> 0.25 | I11: =IF(COUNT(E11:F11)=2,ROUND((F11-E11)*100,2),"") -> 1.79 | J11: =IF(AND(ISNUMBER(E11),ISNUMBER(G11)),ROUND((G11-E11)*100,2),"") -> 2.04 | K11: 기업대출 핵심 비교 | M11: BECBLB0201 | N11: ECOS각종금리데이터.xlsx | O11: 데이터!AR20 | P11: iM뱅크금리2025(잔액).xlsx | Q11: Sheet1!E3
A12: 45689 | B12: 잔액 | C12: 대출 > 기업 | D12: 1 핵심 | E12: =LOOKUP(EOMONTH(A12,0),'출처 및 기준'!$A$34:$A$53,'출처 및 기준'!$B$34:$B$53) -> 0.0275 | F12: 0.0464 | G12: 0.0489 | H12: =IF(COUNT(F12:G12)=2,ROUND((G12-F12)*100,2),"") -> 0.25 | I12: =IF(COUNT(E12:F12)=2,ROUND((F12-E12)*100,2),"") -> 1.89 | J12: =IF(AND(ISNUMBER(E12),ISNUMBER(G12)),ROUND((G12-E12)*100,2),"") -> 2.14 | K12: 기업대출 핵심 비교 | M12: BECBLB0201 | N12: ECOS각종금리데이터.xlsx | O12: 데이터!AQ20 | P12: iM뱅크금리2025(잔액).xlsx | Q12: Sheet1!D3
A13: 45658 | B13: 잔액 | C13: 대출 > 기업 | D13: 1 핵심 | E13: =LOOKUP(EOMONTH(A13,0),'출처 및 기준'!$A$34:$A$53,'출처 및 기준'!$B$34:$B$53) -> 0.03 | F13: 0.0472 | G13: 0.0494 | H13: =IF(COUNT(F13:G13)=2,ROUND((G13-F13)*100,2),"") -> 0.22 | I13: =IF(COUNT(E13:F13)=2,ROUND((F13-E13)*100,2),"") -> 1.72 | J13: =IF(AND(ISNUMBER(E13),ISNUMBER(G13)),ROUND((G13-E13)*100,2),"") -> 1.94 | K13: 기업대출 핵심 비교 | M13: BECBLB0201 | N13: ECOS각종금리데이터.xlsx | O13: 데이터!AP20 | P13: iM뱅크금리2025(잔액).xlsx | Q13: Sheet1!C3
... A161: 45078 | B161: 신규취급액 | C161: 수신 > 순수저축 > 정기 > 1년 | D161: 2 대표 | E161: =LOOKUP(EOMONTH(A161,0),'출처 및 기준'!$A$34:$A$53,'출처 및 기준'!$B$34:$B$53) -> 0.035 | F161: 0.0376 | G161: 0.0346 | H161: =IF(COUNT(F161:G161)=2,ROUND((G161-F161)*100,2),"") -> -0.3 | I161: =IF(COUNT(E161:F161)=2,ROUND((F161-E161)*100,2),"") -> 0.26 | J161: =IF(AND(ISNUMBER(E161),ISNUMBER(G161)),ROUND((G161-E161)*100,2),"") -> -0.04 | K161: 신규 수신 대표 | M161: BEABAA2118 | N161: ECOS각종금리데이터.xlsx | O161: 데이터!W4 | P161: iM뱅크금리2023(순액).xlsx | Q161: Sheet1!H7
A162: 45992 | B162: 신규취급액 | C162: 수신 > 저축성 | D162: 3 보조 | E162: =LOOKUP(EOMONTH(A162,0),'출처 및 기준'!$A$34:$A$53,'출처 및 기준'!$B$34:$B$53) -> 0.025 | F162: 0.029 | G162: 0.0274 | H162: =IF(COUNT(F162:G162)=2,ROUND((G162-F162)*100,2),"") -> -0.16 | I162: =IF(COUNT(E162:F162)=2,ROUND((F162-E162)*100,2),"") -> 0.4 | J162: =IF(AND(ISNUMBER(E162),ISNUMBER(G162)),ROUND((G162-E162)*100,2),"") -> 0.24 | K162: 추가 참고 비교 | L162: 시장: 금융채 제외. iM 포함 범위 미기재 | M162: BEABAA1 | N162: ECOS각종금리데이터.xlsx | O162: 데이터!BA5 | P162: iM뱅크금리2025(순액).xlsx | Q162: Sheet1!N6
A163: 45962 | B163: 신규취급액 | C163: 수신 > 저축성 | D163: 3 보조 | E163: =LOOKUP(EOMONTH(A163,0),'출처 및 기준'!$A$34:$A$53,'출처 및 기준'!$B$34:$B$53) -> 0.025 | F163: 0.028 | G163: 0.0264 | H163: =IF(COUNT(F163:G163)=2,ROUND((G163-F163)*100,2),"") -> -0.16 | I163: =IF(COUNT(E163:F163)=2,ROUND((F163-E163)*100,2),"") -> 0.3 | J163: =IF(AND(ISNUMBER(E163),ISNUMBER(G163)),ROUND((G163-E163)*100,2),"") -> 0.14 | K163: 추가 참고 비교 | L163: 시장: 금융채 제외. iM 포함 범위 미기재 | M163: BEABAA1 | N163: ECOS각종금리데이터.xlsx | O163: 데이터!AZ5 | P163: iM뱅크금리2025(순액).xlsx | Q163: Sheet1!M6
A164: 45931 | B164: 신규취급액 | C164: 수신 > 저축성 | D164: 3 보조 | E164: =LOOKUP(EOMONTH(A164,0),'출처 및 기준'!$A$34:$A$53,'출처 및 기준'!$B$34:$B$53) -> 0.025 | F164: 0.0256 | G164: 0.0248 | H164: =IF(COUNT(F164:G164)=2,ROUND((G164-F164)*100,2),"") -> -0.08 | I164: =IF(COUNT(E164:F164)=2,ROUND((F164-E164)*100,2),"") -> 0.06 | J164: =IF(AND(ISNUMBER(E164),ISNUMBER(G164)),ROUND((G164-E164)*100,2),"") -> -0.02 | K164: 추가 참고 비교 | L164: 시장: 금융채 제외. iM 포함 범위 미기재 | M164: BEABAA1 | N164: ECOS각종금리데이터.xlsx | O164: 데이터!AY5 | P164: iM뱅크금리2025(순액).xlsx | Q164: Sheet1!L6
A165: 45901 | B165: 신규취급액 | C165: 수신 > 저축성 | D165: 3 보조 | E165: =LOOKUP(EOMONTH(A165,0),'출처 및 기준'!$A$34:$A$53,'출처 및 기준'!$B$34:$B$53) -> 0.025 | F165: 0.0252 | G165: 0.0243 | H165: =IF(COUNT(F165:G165)=2,ROUND((G165-F165)*100,2),"") -> -0.09 | I165: =IF(COUNT(E165:F165)=2,ROUND((F165-E165)*100,2),"") -> 0.02 | J165: =IF(AND(ISNUMBER(E165),ISNUMBER(G165)),ROUND((G165-E165)*100,2),"") -> -0.07 | K165: 추가 참고 비교 | L165: 시장: 금융채 제외. iM 포함 범위 미기재 | M165: BEABAA1 | N165: ECOS각종금리데이터.xlsx | O165: 데이터!AX5 | P165: iM뱅크금리2025(순액).xlsx | Q165: Sheet1!K6
A166: 45870 | B166: 신규취급액 | C166: 수신 > 저축성 | D166: 3 보조 | E166: =LOOKUP(EOMONTH(A166,0),'출처 및 기준'!$A$34:$A$53,'출처 및 기준'!$B$34:$B$53) -> 0.025 | F166: 0.0249 | G166: 0.0245 | H166: =IF(COUNT(F166:G166)=2,ROUND((G166-F166)*100,2),"") -> -0.04 | I166: =IF(COUNT(E166:F166)=2,ROUND((F166-E166)*100,2),"") -> -0.01 | J166: =IF(AND(ISNUMBER(E166),ISNUMBER(G166)),ROUND((G166-E166)*100,2),"") -> -0.05 | K166: 추가 참고 비교 | L166: 시장: 금융채 제외. iM 포함 범위 미기재 | M166: BEABAA1 | N166: ECOS각종금리데이터.xlsx | O166: 데이터!AW5 | P166: iM뱅크금리2025(순액).xlsx | Q166: Sheet1!J6
A167: 45839 | B167: 신규취급액 | C167: 수신 > 저축성 | D167: 3 보조 | E167: =LOOKUP(EOMONTH(A167,0),'출처 및 기준'!$A$34:$A$53,'출처 및 기준'!$B$34:$B$53) -> 0.025 | F167: 0.0251 | G167: 0.0241 | H167: =IF(COUNT(F167:G167)=2,ROUND((G167-F167)*100,2),"") -> -0.1 | I167: =IF(COUNT(E167:F167)=2,ROUND((F167-E167)*100,2),"") -> 0.01 | J167: =IF(AND(ISNUMBER(E167),ISNUMBER(G167)),ROUND((G167-E167)*100,2),"") -> -0.09 | K167: 추가 참고 비교 | L167: 시장: 금융채 제외. iM 포함 범위 미기재 | M167: BEABAA1 | N167: ECOS각종금리데이터.xlsx | O167: 데이터!AV5 | P167: iM뱅크금리2025(순액).xlsx | Q167: Sheet1!I6
A168: 45809 | B168: 신규취급액 | C168: 수신 > 저축성 | D168: 3 보조 | E168: =LOOKUP(EOMONTH(A168,0),'출처 및 기준'!$A$34:$A$53,'출처 및 기준'!$B$34:$B$53) -> 0.025 | F168: 0.0255 | G168: 0.0252 | H168: =IF(COUNT(F168:G168)=2,ROUND((G168-F168)*100,2),"") -> -0.03 | I168: =IF(COUNT(E168:F168)=2,ROUND((F168-E168)*100,2),"") -> 0.05 | J168: =IF(AND(ISNUMBER(E168),ISNUMBER(G168)),ROUND((G168-E168)*100,2),"") -> 0.02 | K168: 추가 참고 비교 | L168: 시장: 금융채 제외. iM 포함 범위 미기재 | M168: BEABAA1 | N168: ECOS각종금리데이터.xlsx | O168: 데이터!AU5 | P168: iM뱅크금리2025(순액).xlsx | Q168: Sheet1!H6
A169: 45778 | B169: 신규취급액 | C169: 수신 > 저축성 | D169: 3 보조 | E169: =LOOKUP(EOMONTH(A169,0),'출처 및 기준'!$A$34:$A$53,'출처 및 기준'!$B$34:$B$53) -> 0.025 | F169: 0.0264 | G169: 0.026 | H169: =IF(COUNT(F169:G169)=2,ROUND((G169-F169)*100,2),"") -> -0.04 | I169: =IF(COUNT(E169:F169)=2,ROUND((F169-E169)*100,2),"") -> 0.14 | J169: =IF(AND(ISNUMBER(E169),ISNUMBER(G169)),ROUND((G169-E169)*100,2),"") -> 0.1 | K169: 추가 참고 비교 | L169: 시장: 금융채 제외. iM 포함 범위 미기재 | M169: BEABAA1 | N169: ECOS각종금리데이터.xlsx | O169: 데이터!AT5 | P169: iM뱅크금리2025(순액).xlsx | Q169: Sheet1!G6
A170: 45748 | B170: 신규취급액 | C170: 수신 > 저축성 | D170: 3 보조 | E170: =LOOKUP(EOMONTH(A170,0),'출처 및 기준'!$A$34:$A$53,'출처 및 기준'!$B$34:$B$53) -> 0.0275 | F170: 0.0272 | G170: 0.0268 | H170: =IF(COUNT(F170:G170)=2,ROUND((G170-F170)*100,2),"") -> -0.04 | I170: =IF(COUNT(E170:F170)=2,ROUND((F170-E170)*100,2),"") -> -0.03 | J170: =IF(AND(ISNUMBER(E170),ISNUMBER(G170)),ROUND((G170-E170)*100,2),"") -> -0.07 | K170: 추가 참고 비교 | L170: 시장: 금융채 제외. iM 포함 범위 미기재 | M170: BEABAA1 | N170: ECOS각종금리데이터.xlsx | O170: 데이터!AS5 | P170: iM뱅크금리2025(순액).xlsx | Q170: Sheet1!F6
A171: 45717 | B171: 신규취급액 | C171: 수신 > 저축성 | D171: 3 보조 | E171: =LOOKUP(EOMONTH(A171,0),'출처 및 기준'!$A$34:$A$53,'출처 및 기준'!$B$34:$B$53) -> 0.0275 | F171: 0.0283 | G171: 0.0279 | H171: =IF(COUNT(F171:G171)=2,ROUND((G171-F171)*100,2),"") -> -0.04 | I171: =IF(COUNT(E171:F171)=2,ROUND((F171-E171)*100,2),"") -> 0.08 | J171: =IF(AND(ISNUMBER(E171),ISNUMBER(G171)),ROUND((G171-E171)*100,2),"") -> 0.04 | K171: 추가 참고 비교 | L171: 시장: 금융채 제외. iM 포함 범위 미기재 | M171: BEABAA1 | N171: ECOS각종금리데이터.xlsx | O171: 데이터!AR5 | P171: iM뱅크금리2025(순액).xlsx | Q171: Sheet1!E6
A172: 45689 | B172: 신규취급액 | C172: 수신 > 저축성 | D172: 3 보조 | E172: =LOOKUP(EOMONTH(A172,0),'출처 및 기준'!$A$34:$A$53,'출처 및 기준'!$B$34:$B$53) -> 0.0275 | F172: 0.0297 | G172: 0.0294 | H172: =IF(COUNT(F172:G172)=2,ROUND((G172-F172)*100,2),"") -> -0.03 | I172: =IF(COUNT(E172:F172)=2,ROUND((F172-E172)*100,2),"") -> 0.22 | J172: =IF(AND(ISNUMBER(E172),ISNUMBER(G172)),ROUND((G172-E172)*100,2),"") -> 0.19 | K172: 추가 참고 비교 | L172: 시장: 금융채 제외. iM 포함 범위 미기재 | M172: BEABAA1 | N172: ECOS각종금리데이터.xlsx | O172: 데이터!AQ5 | P172: iM뱅크금리2025(순액).xlsx | Q172: Sheet1!D6
A173: 45658 | B173: 신규취급액 | C173: 수신 > 저축성 | D173: 3 보조 | E173: =LOOKUP(EOMONTH(A173,0),'출처 및 기준'!$A$34:$A$53,'출처 및 기준'!$B$34:$B$53) -> 0.03 | F173: 0.0308 | G173: 0.0296 | H173: =IF(COUNT(F173:G173)=2,ROUND((G173-F173)*100,2),"") -> -0.12 | I173: =IF(COUNT(E173:F173)=2,ROUND((F173-E173)*100,2),"") -> 0.08 | J173: =IF(AND(ISNUMBER(E173),ISNUMBER(G173)),ROUND((G173-E173)*100,2),"") -> -0.04 | K173: 추가 참고 비교 | L173: 시장: 금융채 제외. iM 포함 범위 미기재 | M173: BEABAA1 | N173: ECOS각종금리데이터.xlsx | O173: 데이터!AP5 | P173: iM뱅크금리2025(순액).xlsx | Q173: Sheet1!C6
... A197: 44927 | B197: 신규취급액 | C197: 수신 > 저축성 | D197: 3 보조 | E197: =LOOKUP(EOMONTH(A197,0),'출처 및 기준'!$A$34:$A$53,'출처 및 기준'!$B$34:$B$53) -> 0.035 | F197: 0.0383 | G197: 0.0399 | H197: =IF(COUNT(F197:G197)=2,ROUND((G197-F197)*100,2),"") -> 0.16 | I197: =IF(COUNT(E197:F197)=2,ROUND((F197-E197)*100,2),"") -> 0.33 | J197: =IF(AND(ISNUMBER(E197),ISNUMBER(G197)),ROUND((G197-E197)*100,2),"") -> 0.49 | K197: 추가 참고 비교 | L197: 시장: 금융채 제외. iM 포함 범위 미기재 | M197: BEABAA1 | N197: ECOS각종금리데이터.xlsx | O197: 데이터!R5 | P197: iM뱅크금리2023(순액).xlsx | Q197: Sheet1!C6

Sheet 출처 및 기준
A1: 출처 및 비교 기준
A4: 통합표 범위: 2023.01~2025.12. 기준금리·시장금리·iM뱅크 금리가 모두 채워진 행만 포함.
A5: 포함 조건: 같은 월·집계기준·금리 항목에 세 금리가 모두 숫자로 존재하는 완전 이너조인.
A6: 평균시장금리: 제공된 ECOS 예금은행 통계값. 서로 다른 상품의 금리를 다시 평균내지 않음.
A7: 기준금리: 제공 파일의 변경 이력에서 해당 월말까지 가장 최근 값을 적용. 월평균 금리가 아님.
A8: 집계기준: 사용자 확인에 따라 iM 파일명의 순액을 신규취급액 기준으로 연결. 잔액은 별도 구분.
A9: 수신 범위: 시장 저축성수신은 금융채 제외. iM 포함 범위는 원본에 없어 차이는 참고 비교.
A10: 세 금리 중 하나라도 없으면 행을 제외했습니다. 원본 N/A나 빈칸을 채워 넣지 않았습니다.
A11: 금리는 연 %, 계산한 차이는 %p입니다. 기존 항목 연결과 월말 기준금리 산정 방식을 유지했습니다.
A12: iM−시장: 양수(옅은 주황)는 iM 금리가 더 높고, 음수(옅은 파랑)는 더 낮음을 뜻합니다.
A13: 예대금리차 원본 항목은 세 금리의 존재 조건을 충족하지 않아 통합표에서 제외했습니다.
A14: ECOS 주석: 최종월은 잠정치. 신규 대출은 당좌·마이너스통장 제외, 잔액 대출은 포함.
... A18: 사용한 원본 8개
A19: 원본 파일 | B19: 시작 | C19: 종료 | D19: 내용 | E19: 원본 위치
A20: ECOS각종금리데이터.xlsx | B20: 2022-01 | C20: 2025-12 | D20: 예금은행 금리 23종 · 월별 1,104개 | E20: 데이터!F2:BA24
A21: iM뱅크금리2023(순액).xlsx | B21: 2023-01 | C21: 2023-12 | D21: iM뱅크 11개 항목 · 12개월 | E21: Sheet1!C2:N12
A22: iM뱅크금리2023(잔액).xlsx | B22: 2023-01 | C22: 2023-12 | D22: iM뱅크 11개 항목 · 12개월 | E22: Sheet1!C2:N12
A23: iM뱅크금리2024(순액).xlsx | B23: 2024-01 | C23: 2024-12 | D23: iM뱅크 11개 항목 · 12개월 | E23: Sheet1!C2:N12
A24: iM뱅크금리2024(잔액).xlsx | B24: 2024-01 | C24: 2024-12 | D24: iM뱅크 11개 항목 · 12개월 | E24: Sheet1!C2:N12
A25: iM뱅크금리2025(순액).xlsx | B25: 2025-01 | C25: 2025-12 | D25: iM뱅크 11개 항목 · 12개월 | E25: Sheet1!C2:N12
A26: iM뱅크금리2025(잔액).xlsx | B26: 2025-01 | C26: 2025-12 | D26: iM뱅크 11개 항목 · 12개월 | E26: Sheet1!C2:N12
A27: 기준금리 2019~2026.xlsx | B27: 2019-07-18 | C27: 2026-08-27 | D27: 기준금리 변경 이력 20개 | E27: Sheet1!B2:D21
A30: 기준금리 변경 이력
A31: 원본의 전체 기간을 보존. 통합비교 표에서는 해당 월말에 유효한 값을 참조합니다.
A33: 변경일 | B33: 기준금리 | C33: 단위 | D33: 원본 파일 | E33: 원본 셀
A34: 43664 | B34: 0.015 | C34: 연 % | D34: 기준금리 2019~2026.xlsx | E34: D21
A35: 43754 | B35: 0.0125 | C35: 연 % | D35: 기준금리 2019~2026.xlsx | E35: D20
A36: 43907 | B36: 0.0075 | C36: 연 % | D36: 기준금리 2019~2026.xlsx | E36: D19
A37: 43979 | B37: 0.005 | C37: 연 % | D37: 기준금리 2019~2026.xlsx | E37: D18
A38: 44434 | B38: 0.0075 | C38: 연 % | D38: 기준금리 2019~2026.xlsx | E38: D17
A39: 44525 | B39: 0.01 | C39: 연 % | D39: 기준금리 2019~2026.xlsx | E39: D16
A40: 44575 | B40: 0.0125 | C40: 연 % | D40: 기준금리 2019~2026.xlsx | E40: D15
A41: 44665 | B41: 0.015 | C41: 연 % | D41: 기준금리 2019~2026.xlsx | E41: D14
A42: 44707 | B42: 0.0175 | C42: 연 % | D42: 기준금리 2019~2026.xlsx | E42: D13
A43: 44755 | B43: 0.0225 | C43: 연 % | D43: 기준금리 2019~2026.xlsx | E43: D12
A44: 44798 | B44: 0.025 | C44: 연 % | D44: 기준금리 2019~2026.xlsx | E44: D11
A45: 44846 | B45: 0.03 | C45: 연 % | D45: 기준금리 2019~2026.xlsx | E45: D10
... A53: 46261 | B53: 0.03 | C53: 연 % | D53: 기준금리 2019~2026.xlsx | E53: D2
A56: 연결한 항목
A57: 통합 항목 | B57: 집계기준 | C57: ECOS 코드 | D57: ECOS 원본 항목 | E57: iM 원본 항목
...
